Traceback (most recent call last):
  File "/home/student/dublinbusapp/data/fillTripsTable.py", line 4, in <module>
    import sqlalchemy
ModuleNotFoundError: No module named 'sqlalchemy'
Traceback (most recent call last):
  File "/home/student/dublinbusapp/data/fillLeaveTimesTable.py", line 4, in <module>
    import sqlalchemy
ModuleNotFoundError: No module named 'sqlalchemy'
Traceback (most recent call last):
  File "/home/student/miniconda3/envs/dublinbusenv/lib/python3.10/site-packages/sqlalchemy/engine/base.py", line 1819, in _execute_context
    self.dialect.do_execute(
  File "/home/student/miniconda3/envs/dublinbusenv/lib/python3.10/site-packages/sqlalchemy/engine/default.py", line 732, in do_execute
    cursor.execute(statement, parameters)
  File "/home/student/miniconda3/envs/dublinbusenv/lib/python3.10/site-packages/pymysql/cursors.py", line 148, in execute
    result = self._query(query)
  File "/home/student/miniconda3/envs/dublinbusenv/lib/python3.10/site-packages/pymysql/cursors.py", line 310, in _query
    conn.query(q)
  File "/home/student/miniconda3/envs/dublinbusenv/lib/python3.10/site-packages/pymysql/connections.py", line 548, in query
    self._affected_rows = self._read_query_result(unbuffered=unbuffered)
  File "/home/student/miniconda3/envs/dublinbusenv/lib/python3.10/site-packages/pymysql/connections.py", line 775, in _read_query_result
    result.read()
  File "/home/student/miniconda3/envs/dublinbusenv/lib/python3.10/site-packages/pymysql/connections.py", line 1156, in read
    first_packet = self.connection._read_packet()
  File "/home/student/miniconda3/envs/dublinbusenv/lib/python3.10/site-packages/pymysql/connections.py", line 725, in _read_packet
    packet.raise_for_error()
  File "/home/student/miniconda3/envs/dublinbusenv/lib/python3.10/site-packages/pymysql/protocol.py", line 221, in raise_for_error
    err.raise_mysql_exception(self._data)
  File "/home/student/miniconda3/envs/dublinbusenv/lib/python3.10/site-packages/pymysql/err.py", line 143, in raise_mysql_exception
    raise errorclass(errno, errval)
pymysql.err.OperationalError: (1114, "The table 'leavetimes' is full")

The above exception was the direct cause of the following exception:

Traceback (most recent call last):
  File "/home/student/dublinbusapp/data/fillLeaveTimesTable.py", line 36, in <module>
    connection.execute('INSERT IGNORE INTO leavetimes VALUES ("{}",{},{},{},{},{},{},{},{})'.format(a, b, c, d, e, f, g, h, i))
  File "/home/student/miniconda3/envs/dublinbusenv/lib/python3.10/site-packages/sqlalchemy/engine/base.py", line 1291, in execute
    return self._exec_driver_sql(
  File "/home/student/miniconda3/envs/dublinbusenv/lib/python3.10/site-packages/sqlalchemy/engine/base.py", line 1595, in _exec_driver_sql
    ret = self._execute_context(
  File "/home/student/miniconda3/envs/dublinbusenv/lib/python3.10/site-packages/sqlalchemy/engine/base.py", line 1862, in _execute_context
    self._handle_dbapi_exception(
  File "/home/student/miniconda3/envs/dublinbusenv/lib/python3.10/site-packages/sqlalchemy/engine/base.py", line 2043, in _handle_dbapi_exception
    util.raise_(
  File "/home/student/miniconda3/envs/dublinbusenv/lib/python3.10/site-packages/sqlalchemy/util/compat.py", line 208, in raise_
    raise exception
  File "/home/student/miniconda3/envs/dublinbusenv/lib/python3.10/site-packages/sqlalchemy/engine/base.py", line 1819, in _execute_context
    self.dialect.do_execute(
  File "/home/student/miniconda3/envs/dublinbusenv/lib/python3.10/site-packages/sqlalchemy/engine/default.py", line 732, in do_execute
    cursor.execute(statement, parameters)
  File "/home/student/miniconda3/envs/dublinbusenv/lib/python3.10/site-packages/pymysql/cursors.py", line 148, in execute
    result = self._query(query)
  File "/home/student/miniconda3/envs/dublinbusenv/lib/python3.10/site-packages/pymysql/cursors.py", line 310, in _query
    conn.query(q)
  File "/home/student/miniconda3/envs/dublinbusenv/lib/python3.10/site-packages/pymysql/connections.py", line 548, in query
    self._affected_rows = self._read_query_r